<sdf version='1.9'>
  <model name='ur'>
    <joint name='base_joint' type='fixed'>
      <pose relative_to='__model__'>0 0 0 0 0 0</pose>
      <parent>world</parent>
      <child>base_link</child>
    </joint>
    <link name='base_link'>
      <pose relative_to='base_joint'>0 0 0 0 0 0</pose>
      <inertial>
        <pose>0 0 0 0 0 0</pose>
        <mass>4</mass>
        <inertia>
          <ixx>0.0044333315599999999</ixx>
          <ixy>0</ixy>
          <ixz>0</ixz>
          <iyy>0.0044333315599999999</iyy>
          <iyz>0</iyz>
          <izz>0.0071999999999999998</izz>
        </inertia>
      </inertial>
      <collision name='base_link_inertia_collision'>
        <pose>0 0 0 0 0 -2.449293598294706e-16</pose>
        <geometry>
          <mesh>
            <scale>1 1 1</scale>
            <uri>model://ur_description/meshes/ur5e/collision/base.stl</uri>
          </mesh>
        </geometry>
      </collision>
      <visual name='base_link_inertia_visual'>
        <pose>0 0 0 0 0 -2.449293598294706e-16</pose>
        <geometry>
          <mesh>
            <scale>1 1 1</scale>
            <uri>model://ur_description/meshes/ur5e/visual/base.dae</uri>
          </mesh>
        </geometry>
      </visual>
    </link>
    <joint name='shoulder_pan_joint' type='revolute'>
      <pose relative_to='base_link'>0 0 0.1625 0 0 3.141592653589793</pose>
      <parent>base_link</parent>
      <child>shoulder_link</child>
      <axis>
        <xyz>0 0 1</xyz>
        <limit>
          <lower>-6.2831853071795862</lower>
          <upper>6.2831853071795862</upper>
          <effort>150</effort>
          <velocity>3.1415926535897931</velocity>
        </limit>
        <dynamics>
          <damping>0</damping>
          <friction>0</friction>
          <spring_reference>0</spring_reference>
          <spring_stiffness>0</spring_stiffness>
        </dynamics>
      </axis>
    </joint>
    <link name='shoulder_link'>
      <pose relative_to='shoulder_pan_joint'>0 0 0 0 0 0</pose>
      <inertial>
        <pose>0 -0.00193 -0.02561 1.570796326794897 0 0</pose>
        <mass>3.7610000000000001</mass>
        <inertia>
          <ixx>0.0070020999999999998</ixx>
          <ixy>7.3e-07</ixy>
          <ixz>-1.0530000000000001e-05</ixz>
          <iyy>0.0064809100000000003</iyy>
          <iyz>0.00049994000000000004</iyz>
          <izz>0.0065728599999999998</izz>
        </inertia>
      </inertial>
      <collision name='shoulder_link_collision'>
        <pose>0 0 0 0 0 3.141592653589793</pose>
        <geometry>
          <mesh>
            <scale>1 1 1</scale>
            <uri>model://ur_description/meshes/ur5e/collision/shoulder.stl</uri>
          </mesh>
        </geometry>
      </collision>
      <visual name='shoulder_link_visual'>
        <pose>0 0 0 0 0 3.141592653589793</pose>
        <geometry>
          <mesh>
            <scale>1 1 1</scale>
            <uri>model://ur_description/meshes/ur5e/visual/shoulder.dae</uri>
          </mesh>
        </geometry>
      </visual>
    </link>
    <joint name='shoulder_lift_joint' type='revolute'>
      <pose relative_to='shoulder_link'>0 0 0 1.570796327 0 0</pose>
      <parent>shoulder_link</parent>
      <child>upper_arm_link</child>
      <axis>
        <xyz>0 0 1</xyz>
        <limit>
          <lower>-6.2831853071795862</lower>
          <upper>6.2831853071795862</upper>
          <effort>150</effort>
          <velocity>3.1415926535897931</velocity>
        </limit>
        <dynamics>
          <damping>0</damping>
          <friction>0</friction>
          <spring_reference>0</spring_reference>
          <spring_stiffness>0</spring_stiffness>
        </dynamics>
      </axis>
    </joint>
    <link name='upper_arm_link'>
      <pose relative_to='shoulder_lift_joint'>0 0 0 0 0 0</pose>
      <inertial>
        <pose>-0.2125 0 0.11336 0 0 0</pose>
        <mass>8.0579999999999998</mass>
        <inertia>
          <ixx>0.01505885</ixx>
          <ixy>-5.3999999999999998e-05</ixy>
          <ixz>5.6300000000000003e-06</ixz>
          <iyy>0.33388086</iyy>
          <iyz>-1.81e-06</iyz>
          <izz>0.33247207000000001</izz>
        </inertia>
      </inertial>
      <collision name='upper_arm_link_collision'>
        <pose>0 0 0.138 1.570796326794896 0 -1.570796326794896</pose>
        <geometry>
          <mesh>
            <scale>1 1 1</scale>
            <uri>model://ur_description/meshes/ur5e/collision/upperarm.stl</uri>
          </mesh>
        </geometry>
      </collision>
      <visual name='upper_arm_link_visual'>
        <pose>0 0 0.138 1.570796326794896 0 -1.570796326794896</pose>
        <geometry>
          <mesh>
            <scale>1 1 1</scale>
            <uri>model://ur_description/meshes/ur5e/visual/upperarm.dae</uri>
          </mesh>
        </geometry>
      </visual>
    </link>
    <joint name='elbow_joint' type='revolute'>
      <pose relative_to='upper_arm_link'>-0.425 0 0 0 0 0</pose>
      <parent>upper_arm_link</parent>
      <child>forearm_link</child>
      <axis>
        <xyz>0 0 1</xyz>
        <limit>
          <lower>-3.1415926535897931</lower>
          <upper>3.1415926535897931</upper>
          <effort>150</effort>
          <velocity>3.1415926535897931</velocity>
        </limit>
        <dynamics>
          <damping>0</damping>
          <friction>0</friction>
          <spring_reference>0</spring_reference>
          <spring_stiffness>0</spring_stiffness>
        </dynamics>
      </axis>
    </joint>
    <link name='forearm_link'>
      <pose relative_to='elbow_joint'>0 0 0 0 0 0</pose>
      <inertial>
        <pose>-0.2422 0 0.0265 0 0 0</pose>
        <mass>2.8460000000000001</mass>
        <inertia>
          <ixx>0.0039963200000000003</ixx>
          <ixy>-1.365e-05</ixy>
          <ixz>0.00137272</ixz>
          <iyy>0.078792539999999994</iyy>
          <iyz>-6.6000000000000003e-06</iyz>
          <izz>0.078485100000000002</izz>
        </inertia>
      </inertial>
      <collision name='forearm_link_collision'>
        <pose>0 0 0.007 1.570796326794896 0 -1.570796326794896</pose>
        <geometry>
          <mesh>
            <scale>1 1 1</scale>
            <uri>model://ur_description/meshes/ur5e/collision/forearm.stl</uri>
          </mesh>
        </geometry>
      </collision>
      <visual name='forearm_link_visual'>
        <pose>0 0 0.007 1.570796326794896 0 -1.570796326794896</pose>
        <geometry>
          <mesh>
            <scale>1 1 1</scale>
            <uri>model://ur_description/meshes/ur5e/visual/forearm.dae</uri>
          </mesh>
        </geometry>
      </visual>
    </link>
    <joint name='wrist_1_joint' type='revolute'>
      <pose relative_to='forearm_link'>-0.3922 0 0.1333 0 0 0</pose>
      <parent>forearm_link</parent>
      <child>wrist_1_link</child>
      <axis>
        <xyz>0 0 1</xyz>
        <limit>
          <lower>-6.2831853071795862</lower>
          <upper>6.2831853071795862</upper>
          <effort>28</effort>
          <velocity>3.1415926535897931</velocity>
        </limit>
        <dynamics>
          <damping>0</damping>
          <friction>0</friction>
          <spring_reference>0</spring_reference>
          <spring_stiffness>0</spring_stiffness>
        </dynamics>
      </axis>
    </joint>
    <link name='wrist_1_link'>
      <pose relative_to='wrist_1_joint'>0 0 0 0 0 0</pose>
      <inertial>
        <pose>0 -0.01634 -0.0018 1.570796326794897 0 0</pose>
        <mass>1.3700000000000001</mass>
        <inertia>
          <ixx>0.0016549100000000001</ixx>
          <ixy>-2.8200000000000001e-06</ixy>
          <ixz>-4.3800000000000004e-06</ixz>
          <iyy>0.00135962</iyy>
          <iyz>0.00010157000000000001</iyz>
          <izz>0.00126279</izz>
        </inertia>
      </inertial>
      <collision name='wrist_1_link_collision'>
        <pose>0 0 -0.127 1.570796326794896 0 0</pose>
        <geometry>
          <mesh>
            <scale>1 1 1</scale>
            <uri>model://ur_description/meshes/ur5e/collision/wrist1.stl</uri>
          </mesh>
        </geometry>
      </collision>
      <visual name='wrist_1_link_visual'>
        <pose>0 0 -0.127 1.570796326794896 0 0</pose>
        <geometry>
          <mesh>
            <scale>1 1 1</scale>
            <uri>model://ur_description/meshes/ur5e/visual/wrist1.dae</uri>
          </mesh>
        </geometry>
      </visual>
    </link>
    <joint name='wrist_2_joint' type='revolute'>
      <pose relative_to='wrist_1_link'>0 -0.0997 -2.044881182297852e-11 1.570796327 0 0</pose>
      <parent>wrist_1_link</parent>
      <child>wrist_2_link</child>
      <axis>
        <xyz>0 0 1</xyz>
        <limit>
          <lower>-6.2831853071795862</lower>
          <upper>6.2831853071795862</upper>
          <effort>28</effort>
          <velocity>3.1415926535897931</velocity>
        </limit>
        <dynamics>
          <damping>0</damping>
          <friction>0</friction>
          <spring_reference>0</spring_reference>
          <spring_stiffness>0</spring_stiffness>
        </dynamics>
      </axis>
    </joint>
    <link name='wrist_2_link'>
      <pose relative_to='wrist_2_joint'>0 0 0 0 0 0</pose>
      <inertial>
        <pose>0 0.01634 -0.0018 -1.570796326794897 0 0</pose>
        <mass>1.3</mass>
        <inertia>
          <ixx>0.0013561700000000001</ixx>
          <ixy>-2.74e-06</ixy>
          <ixz>4.4399999999999998e-06</ixz>
          <iyy>0.00127827</iyy>
          <iyz>-5.0479999999999998e-05</iyz>
          <izz>0.00096613999999999999</izz>
        </inertia>
      </inertial>
      <collision name='wrist_2_link_collision'>
        <pose>0 0 -0.0997 0 0 0</pose>
        <geometry>
          <mesh>
            <scale>1 1 1</scale>
            <uri>model://ur_description/meshes/ur5e/collision/wrist2.stl</uri>
          </mesh>
        </geometry>
      </collision>
      <visual name='wrist_2_link_visual'>
        <pose>0 0 -0.0997 0 0 0</pose>
        <geometry>
          <mesh>
            <scale>1 1 1</scale>
            <uri>model://ur_description/meshes/ur5e/visual/wrist2.dae</uri>
          </mesh>
        </geometry>
      </visual>
    </link>
    <joint name='wrist_3_joint' type='revolute'>
      <pose relative_to='wrist_2_link'>0 0.09959999999999999 -2.042830148012698e-11 -1.570796327 1.224646799147353e-16 -1.224646799147353e-16</pose>
      <parent>wrist_2_link</parent>
      <child>wrist_3_link</child>
      <axis>
        <xyz>0 0 1</xyz>
        <limit>
          <lower>-6.2831853071795862</lower>
          <upper>6.2831853071795862</upper>
          <effort>28</effort>
          <velocity>3.1415926535897931</velocity>
        </limit>
        <dynamics>
          <damping>0</damping>
          <friction>0</friction>
          <spring_reference>0</spring_reference>
          <spring_stiffness>0</spring_stiffness>
        </dynamics>
      </axis>
    </joint>
    <link name='wrist_3_link'>
      <pose relative_to='wrist_3_joint'>0 0 0 0 0 0</pose>
      <inertial>
        <pose>0 0 -0.001159 0 0 0</pose>
        <mass>0.36499999999999999</mass>
        <inertia>
          <ixx>0.00018694</ixx>
          <ixy>5.9999999999999995e-08</ixy>
          <ixz>-1.6999999999999999e-07</ixz>
          <iyy>0.00018908</iyy>
          <iyz>-9.1999999999999998e-07</iyz>
          <izz>0.00025755999999999999</izz>
        </inertia>
      </inertial>
      <collision name='wrist_3_link_collision'>
        <pose>0 0 -0.0989 1.570796326794896 0 0</pose>
        <geometry>
          <mesh>
            <scale>1 1 1</scale>
            <uri>model://ur_description/meshes/ur5e/collision/wrist3.stl</uri>
          </mesh>
        </geometry>
      </collision>
      <visual name='wrist_3_link_visual'>
        <pose>0 0 -0.0989 1.570796326794896 0 0</pose>
        <geometry>
          <mesh>
            <scale>1 1 1</scale>
            <uri>model://ur_description/meshes/ur5e/visual/wrist3.dae</uri>
          </mesh>
        </geometry>
      </visual>
    </link>
    <frame name='base_link-base_fixed_joint' attached_to='base_link'>
      <pose>0 0 0 0 -0 3.14159</pose>
    </frame>
    <frame name='base' attached_to='base_link-base_fixed_joint'/>
    <frame name='base_link-base_link_inertia' attached_to='base_link'>
      <pose>0 0 0 0 -0 3.14159</pose>
    </frame>
    <frame name='base_link_inertia' attached_to='base_link-base_link_inertia'/>
    <frame name='flange-tool0' attached_to='flange'>
      <pose>0 0 0 1.5708 -0 1.5708</pose>
    </frame>
    <frame name='tool0' attached_to='flange-tool0'/>
    <frame name='wrist_3-flange' attached_to='wrist_3_link'>
      <pose>0 0 0 -1.5708 -1.5708 0</pose>
    </frame>
    <frame name='flange' attached_to='wrist_3-flange'/>
    <frame name='wrist_3_link-ft_frame' attached_to='wrist_3_link'>
      <pose>0 0 0 3.14159 -0 0</pose>
    </frame>
    <frame name='ft_frame' attached_to='wrist_3_link-ft_frame'/>
  </model>
</sdf>
